Workbook

Sheet Guide
B1: A 10-Year Comparative Study on Performance of Sensex, Gold, and HDFC Flexi Cap Fund (2015–2024)
B2: Sensex (Equity Index) • Gold • HDFC Flexi Cap (Mutual Fund) | Jan-2015 to Dec-2024 | Built on daily returns
B4: What this workbook does
B5: Purpose | C5: Helps an investor compare three very different assets — an equity index, gold, and an actively-managed flexi-cap fund — and shows why blending them (diversification) can improve the risk-adjusted outcome. Everything is derived from DAILY price data, which is far more accurate than annual figures for risk metrics (volatility, drawdown, VaR, correlation).
B6: How to use it | C6: Change any input on the Assumptions sheet (allocation, risk-free rate, investment amounts). Every metric, chart-feed and table recalculates automatically. Then point Power BI / Excel charts at the 'Dashboard Data' and daily sheets.
B8: Sheet map
B9: Assumptions | C9: All editable inputs in one place — portfolio weights, risk-free rate, lumpsum & SIP amounts, annualisation factor, VaR confidence. Blue = you can change it.
B10: Daily Prices | C10: Cleaned, date-aligned daily levels for all three assets (only days when all three traded, so cross-asset stats are valid). This is the raw input — blue.
B11: Daily Returns | C11: Daily % change for each asset + the blended portfolio (constant-weight). The engine behind every risk statistic.
B12: Growth Index | C12: Growth of ₹100 and of your lumpsum, compounded daily. Feeds the 'growth' line chart.
B13: Drawdowns | C13: Running peak-to-trough loss for each asset & the portfolio. Feeds the 'underwater' chart — the most intuitive picture of risk.
B14: Rolling 1Y | C14: 252-day rolling annualised return, volatility, Sharpe, and rolling correlations — shows how risk & diversification change over time.
B15: Annual Returns | C15: Calendar-year returns per asset — source for the year-by-year bar/heatmap.
B16: Monthly Returns | C16: Month-by-month return matrix per asset — seasonality heatmap source.
B17: Correlation | C17: Daily-return correlation & covariance matrices — the statistical core of the diversification story.
B18: Metrics Summary | C18: The master scorecard: CAGR, volatility, Sharpe, Sortino, Calmar, max drawdown, VaR, CVaR, skew, kurtosis, beta, % positive days, best/worst day — per asset and for the blended portfolio.
B19: Investment Growth | C19: Lumpsum & SIP outcomes, including XIRR (money-weighted return) for a monthly SIP.
B20: Dashboard Data | C20: Tidy long-format tables (metrics & annual returns) ready to 'Get Data' straight into Power BI.
B22: Methodology notes
B23: • | C23: Alignment: only trading days on which ALL three assets have a real observation are kept (2,186 days). This avoids fake zero-return days and keeps correlations honest.
B24: • | C24: Daily simple returns are used for volatility, VaR, correlation and Sharpe (industry convention); geometric compounding is used for growth and CAGR.
B25: • | C25: The blended portfolio is constant-weight (daily-rebalanced) at the Assumptions weights, so its volatility correctly reflects diversification.
B26: • | C26: Annualisation uses the factor on the Assumptions sheet (252 by default). Sharpe/Sortino use the editable risk-free rate.
B27: • | C27: This is a research/education tool built from historical data. Past performance does not guarantee future results — it is not personalised investment advice.
B29: ⚠ Data-quality note (read before presenting)
B30: Sensex & Gold | C30: Daily series are clean — every daily metric (volatility, VaR, drawdown, correlation) is fully reliable.
B31: HDFC Flexi Cap | C31: The raw daily NAV feed contained 364 isolated bad values (spikes concentrated on month-boundary dates such as the 1st and 13th) that produced impossible single-day moves of 20-30%. These were repaired with a documented trend-median filter that preserves the fund's true trajectory and endpoints (its CAGR is unchanged). HDFC's CAGR, annual returns and growth figures are reliable; treat its day-level volatility / VaR as indicative and, for a publication-grade result, re-source clean daily NAV from AMFI.
B32: Why this matters | C32: A real equity fund should move closely with the equity index day-to-day. The raw HDFC feed did not — a red flag that the source, not the market, was the problem. Being upfront about this is exactly the kind of rigour that makes an investment-analysis project credible.
B34: Tip | C34: For a polished dashboard: use Growth Index for the hero line chart, Drawdowns for the underwater area chart, Correlation for a heatmap, Monthly Returns for a seasonality heatmap, and Metrics Summary cards for the KPI tiles.

Sheet Assumptions
B1: Assumptions & Parameters
B2: Change any blue value — the whole workbook recalculates. Yellow = key drivers.
B4: Investment & Risk Parameters
B5: Parameter | C5: Value | D5: Notes
B6: Lumpsum Investment (₹) | C6: 100000 | D6: One-time investment at the start of the period.
B7: SIP Monthly Amount (₹) | C7: 5000 | D7: Fixed amount invested every month across the period.
B8: Risk-Free Rate (annual) | C8: 0.065 | D8: Approx. 10-yr India G-Sec yield. Used for Sharpe / Sortino / Treynor.
B9: Annualisation Factor (days/yr) | C9: 252 | D9: Trading days per year used to annualise daily stats.
B10: VaR / CVaR Confidence | C10: 0.95 | D10: e.g. 0.95 = 95% one-day Value-at-Risk.
B12: Portfolio Allocation (constant-weight, daily-rebalanced)
B13: Asset Class | C13: Weight | D13: Notes
B14: Gold | C14: 0.4 | D14: Weights must sum to 100%.
B15: Sensex (Equity) | C15: 0.3
B16: HDFC Flexi Cap (Fund) | C16: 0.3
B17: Total | C17: =C14+C15+C16 -> 1 | D17: Should equal 100%.
B18: Weight check | C18: =IF(ROUND(C17,4)=1,"OK ✓","FIX — must total 100%") -> OK ✓

Sheet Metrics Summary
A1: Metrics Summary — master scorecard (daily-data based)
A2: Every figure is a live formula. Sharpe / Sortino / Treynor use the risk-free rate on Assumptions.
A3: Metric | B3: Sensex | C3: Gold | D3: HDFC Flexi Cap | E3: Portfolio
A4: PERFORMANCE
A5: Trading days observed | B5: =COUNT('Daily Returns'!B$4:B$2188) -> 2185 | C5: =COUNT('Daily Returns'!C$4:C$2188) -> 2185 | D5: =COUNT('Daily Returns'!D$4:D$2188) -> 2185 | E5: =COUNT('Daily Returns'!E$4:E$2188) -> 2185
A6: Years covered | B6: =('Daily Prices'!$A$2188-'Daily Prices'!$A$3)/365.25 -> 9.9986311 | C6: =('Daily Prices'!$A$2188-'Daily Prices'!$A$3)/365.25 -> 9.9986311 | D6: =('Daily Prices'!$A$2188-'Daily Prices'!$A$3)/365.25 -> 9.9986311 | E6: =('Daily Prices'!$A$2188-'Daily Prices'!$A$3)/365.25 -> 9.9986311
A7: Total return (cumulative) | B7: ='Growth Index'!B$2188/'Growth Index'!B$3-1 -> 1.8406397 | C7: ='Growth Index'!C$2188/'Growth Index'!C$3-1 -> 1.9224923 | D7: ='Growth Index'!D$2188/'Growth Index'!D$3-1 -> 3.2531413 | E7: ='Growth Index'!E$2188/'Growth Index'!E$3-1 -> 2.5293122
A8: CAGR (annualised) | B8: =('Growth Index'!B$2188/'Growth Index'!B$3)^(1/((('Daily Prices'!$A$2188-'Daily Prices'!$A$3)/365.25)))-1 -> 0.1100635 | C8: =('Growth Index'!C$2188/'Growth Index'!C$3)^(1/((('Daily Prices'!$A$2188-'Daily Prices'!$A$3)/365.25)))-1 -> 0.11322183 | D8: =('Growth Index'!D$2188/'Growth Index'!D$3)^(1/((('Daily Prices'!$A$2188-'Daily Prices'!$A$3)/365.25)))-1 -> 0.15579175 | E8: =('Growth Index'!E$2188/'Growth Index'!E$3)^(1/((('Daily Prices'!$A$2188-'Daily Prices'!$A$3)/365.25)))-1 -> 0.13442687
A9: Ann. return (arithmetic mean) | B9: =AVERAGE('Daily Returns'!B$4:B$2188)*Assumptions!$C$9 -> 0.1366159 | C9: =AVERAGE('Daily Returns'!C$4:C$2188)*Assumptions!$C$9 -> 0.13553013 | D9: =AVERAGE('Daily Returns'!D$4:D$2188)*Assumptions!$C$9 -> 0.18915122 | E9: =AVERAGE('Daily Returns'!E$4:E$2188)*Assumptions!$C$9 -> 0.15194219
A10: RISK
A11: Ann. volatility (std dev) | B11: =STDEV('Daily Returns'!B$4:B$2188)*SQRT(Assumptions!$C$9) -> 0.17923057 | C11: =STDEV('Daily Returns'!C$4:C$2188)*SQRT(Assumptions!$C$9) -> 0.15388333 | D11: =STDEV('Daily Returns'!D$4:D$2188)*SQRT(Assumptions!$C$9) -> 0.210804 | E11: =STDEV('Daily Returns'!E$4:E$2188)*SQRT(Assumptions!$C$9) -> 0.11355571
A12: Downside deviation (ann.) | B12: =SQRT(SUMPRODUCT(('Daily Returns'!B$4:B$2188<0)*('Daily Returns'!B$4:B$2188)^2)/COUNT('Daily Returns'!B$4:B$2188))*SQRT(Assumptions!$C$9) -> 0.12890835 | C12: =SQRT(SUMPRODUCT(('Daily Returns'!C$4:C$2188<0)*('Daily Returns'!C$4:C$2188)^2)/COUNT('Daily Returns'!C$4:C$2188))*SQRT(Assumptions!$C$9) -> 0.10221123 | D12: =SQRT(SUMPRODUCT(('Daily Returns'!D$4:D$2188<0)*('Daily Returns'!D$4:D$2188)^2)/COUNT('Daily Returns'!D$4:D$2188))*SQRT(Assumptions!$C$9) -> 0.1400823 | E12: =SQRT(SUMPRODUCT(('Daily Returns'!E$4:E$2188<0)*('Daily Returns'!E$4:E$2188)^2)/COUNT('Daily Returns'!E$4:E$2188))*SQRT(Assumptions!$C$9) -> 0.077258585
A13: Maximum drawdown | B13: =MIN(Drawdowns!B$3:B$2188) -> -0.38070057 | C13: =MIN(Drawdowns!C$3:C$2188) -> -0.20141514 | D13: =MIN(Drawdowns!D$3:D$2188) -> -0.36263947 | E13: =MIN(Drawdowns!E$3:E$2188) -> -0.22083249
A14: Best single day | B14: =MAX('Daily Returns'!B$4:B$2188) -> 0.083469761 | C14: =MAX('Daily Returns'!C$4:C$2188) -> 0.071344533 | D14: =MAX('Daily Returns'!D$4:D$2188) -> 0.087077166 | E14: =MAX('Daily Returns'!E$4:E$2188) -> 0.038247361
A15: Worst single day | B15: =MIN('Daily Returns'!B$4:B$2188) -> -0.13152578 | C15: =MIN('Daily Returns'!C$4:C$2188) -> -0.056991962 | D15: =MIN('Daily Returns'!D$4:D$2188) -> -0.076890051 | E15: =MIN('Daily Returns'!E$4:E$2188) -> -0.05822814
A16: Positive days | B16: =COUNTIF('Daily Returns'!B$4:B$2188,">0")/COUNT('Daily Returns'!B$4:B$2188) -> 0.53913043 | C16: =COUNTIF('Daily Returns'!C$4:C$2188,">0")/COUNT('Daily Returns'!C$4:C$2188) -> 0.50297483 | D16: =COUNTIF('Daily Returns'!D$4:D$2188,">0")/COUNT('Daily Returns'!D$4:D$2188) -> 0.54828375 | E16: =COUNTIF('Daily Returns'!E$4:E$2188,">0")/COUNT('Daily Returns'!E$4:E$2188) -> 0.54508009
A17: Skewness (daily) | B17: =SKEW('Daily Returns'!B$4:B$2188) -> -0.92196323 | C17: =SKEW('Daily Returns'!C$4:C$2188) -> 0.24129046 | D17: =SKEW('Daily Returns'!D$4:D$2188) -> 0.37183282 | E17: =SKEW('Daily Returns'!E$4:E$2188) -> -0.42133591
A18: Excess kurtosis (daily) | B18: =KURT('Daily Returns'!B$4:B$2188) -> 16.43674 | C18: =KURT('Daily Returns'!C$4:C$2188) -> 4.5321777 | D18: =KURT('Daily Returns'!D$4:D$2188) -> 5.5628952 | E18: =KURT('Daily Returns'!E$4:E$2188) -> 5.7345676
A19: 1-day VaR (historical) | B19: =PERCENTILE('Daily Returns'!B$4:B$2188,1-Assumptions!$C$10) -> -0.015596879 | C19: =PERCENTILE('Daily Returns'!C$4:C$2188,1-Assumptions!$C$10) -> -0.014509751 | D19: =PERCENTILE('Daily Returns'!D$4:D$2188,1-Assumptions!$C$10) -> -0.020420479 | E19: =PERCENTILE('Daily Returns'!E$4:E$2188,1-Assumptions!$C$10) -> -0.010336772
A20: 1-day CVaR / Expected Shortfall | B20: =AVERAGEIF('Daily Returns'!B$4:B$2188,"<="&B19) -> -0.026264095 | C20: =AVERAGEIF('Daily Returns'!C$4:C$2188,"<="&C19) -> -0.021526095 | D20: =AVERAGEIF('Daily Returns'!D$4:D$2188,"<="&D19) -> -0.029625092 | E20: =AVERAGEIF('Daily Returns'!E$4:E$2188,"<="&E19) -> -0.015673043
A21: RISK-ADJUSTED & MARKET
A22: Sharpe ratio | B22: =(B9-Assumptions!$C$8)/B11 -> 0.39957415 | C22: =(C9-Assumptions!$C$8)/C11 -> 0.4583351 | D22: =(D9-Assumptions!$C$8)/D11 -> 0.5889415 | E22: =(E9-Assumptions!$C$8)/E11 -> 0.76563468
A23: Sortino ratio | B23: =(B9-Assumptions!$C$8)/B12 -> 0.55555677 | C23: =(C9-Assumptions!$C$8)/C12 -> 0.69004287 | D23: =(D9-Assumptions!$C$8)/D12 -> 0.88627345 | E23: =(E9-Assumptions!$C$8)/E12 -> 1.1253402
A24: Calmar ratio | B24: =ABS(B8/B13) -> 0.28910779 | C24: =ABS(C8/C13) -> 0.56213168 | D24: =ABS(D8/D13) -> 0.42960504 | E24: =ABS(E8/E13) -> 0.60872779
A25: Beta (vs Sensex) | B25: =SLOPE('Daily Returns'!B$4:B$2188,'Daily Returns'!B$4:B$2188) -> 1 | C25: =SLOPE('Daily Returns'!C$4:C$2188,'Daily Returns'!B$4:B$2188) -> -0.06193432 | D25: =SLOPE('Daily Returns'!D$4:D$2188,'Daily Returns'!B$4:B$2188) -> 0.52533842 | E25: =SLOPE('Daily Returns'!E$4:E$2188,'Daily Returns'!B$4:B$2188) -> 0.4328278
A26: Treynor ratio | B26: =(B9-Assumptions!$C$8)/B25 -> 0.071615904 | C26: =(C9-Assumptions!$C$8)/C25 -> -1.1387892 | D26: =(D9-Assumptions!$C$8)/D25 -> 0.23632618 | E26: =(E9-Assumptions!$C$8)/E25 -> 0.20087016
A27: Correlation to Sensex | B27: =CORREL('Daily Returns'!B$4:B$2188,'Daily Returns'!B$4:B$2188) -> 1 | C27: =CORREL('Daily Returns'!C$4:C$2188,'Daily Returns'!B$4:B$2188) -> -0.072135972 | D27: =CORREL('Daily Returns'!D$4:D$2188,'Daily Returns'!B$4:B$2188) -> 0.44665522 | E27: =CORREL('Daily Returns'!E$4:E$2188,'Daily Returns'!B$4:B$2188) -> 0.68315344
A28: INVESTMENT OUTCOME
A29: Lumpsum final value | B29: =Assumptions!$C$6*(1+B7) -> 284063.97 | C29: =Assumptions!$C$6*(1+C7) -> 292249.23 | D29: =Assumptions!$C$6*(1+D7) -> 425314.13 | E29: =Assumptions!$C$6*(1+E7) -> 352931.22

Sheet Charts
A1: Charts — starter visuals (build your dashboard from here)
A2: Native Excel charts linked to the live data. Duplicate, restyle, or rebuild in Power BI as you like.
A40: Asset | B40: Volatility | C40: CAGR
A41: Sensex | B41: ='Metrics Summary'!B11 -> 0.17923057 | C41: ='Metrics Summary'!B8 -> 0.1100635
A42: Gold | B42: ='Metrics Summary'!C11 -> 0.15388333 | C42: ='Metrics Summary'!C8 -> 0.11322183
A43: HDFC Flexi Cap | B43: ='Metrics Summary'!D11 -> 0.210804 | C43: ='Metrics Summary'!D8 -> 0.15579175
A44: Portfolio | B44: ='Metrics Summary'!E11 -> 0.11355571 | C44: ='Metrics Summary'!E8 -> 0.13442687

Sheet Correlation
A1: Correlation & Covariance — the diversification engine
A2: Computed from daily simple returns. Low / negative correlation is what makes blending assets reduce risk.
A4: Correlation Matrix (daily returns)
B5: Sensex | C5: Gold | D5: HDFC Flexi Cap | E5: Portfolio
A6: Sensex | B6: =CORREL('Daily Returns'!B$4:B$2188,'Daily Returns'!B$4:B$2188) -> 1 | C6: =CORREL('Daily Returns'!B$4:B$2188,'Daily Returns'!C$4:C$2188) -> -0.072135972 | D6: =CORREL('Daily Returns'!B$4:B$2188,'Daily Returns'!D$4:D$2188) -> 0.44665522 | E6: =CORREL('Daily Returns'!B$4:B$2188,'Daily Returns'!E$4:E$2188) -> 0.68315344
A7: Gold | B7: =CORREL('Daily Returns'!C$4:C$2188,'Daily Returns'!B$4:B$2188) -> -0.072135972 | C7: =CORREL('Daily Returns'!C$4:C$2188,'Daily Returns'!C$4:C$2188) -> 1 | D7: =CORREL('Daily Returns'!C$4:C$2188,'Daily Returns'!D$4:D$2188) -> -0.044266172 | E7: =CORREL('Daily Returns'!C$4:C$2188,'Daily Returns'!E$4:E$2188) -> 0.4832447
A8: HDFC Flexi Cap | B8: =CORREL('Daily Returns'!D$4:D$2188,'Daily Returns'!B$4:B$2188) -> 0.44665522 | C8: =CORREL('Daily Returns'!D$4:D$2188,'Daily Returns'!C$4:C$2188) -> -0.044266172 | D8: =CORREL('Daily Returns'!D$4:D$2188,'Daily Returns'!D$4:D$2188) -> 1 | E8: =CORREL('Daily Returns'!D$4:D$2188,'Daily Returns'!E$4:E$2188) -> 0.74441654
A9: Portfolio | B9: =CORREL('Daily Returns'!E$4:E$2188,'Daily Returns'!B$4:B$2188) -> 0.68315344 | C9: =CORREL('Daily Returns'!E$4:E$2188,'Daily Returns'!C$4:C$2188) -> 0.4832447 | D9: =CORREL('Daily Returns'!E$4:E$2188,'Daily Returns'!D$4:D$2188) -> 0.74441654 | E9: =CORREL('Daily Returns'!E$4:E$2188,'Daily Returns'!E$4:E$2188) -> 1
A11: Annualised Covariance Matrix
B12: Sensex | C12: Gold | D12: HDFC Flexi Cap | E12: Portfolio
A13: Sensex | B13: =_xlfn.COVARIANCE.S('Daily Returns'!B$4:B$2188,'Daily Returns'!B$4:B$2188)*Assumptions!$C$9 -> 0.032123599 | C13: =_xlfn.COVARIANCE.S('Daily Returns'!B$4:B$2188,'Daily Returns'!C$4:C$2188)*Assumptions!$C$9 -> -0.0019895533 | D13: =_xlfn.COVARIANCE.S('Daily Returns'!B$4:B$2188,'Daily Returns'!D$4:D$2188)*Assumptions!$C$9 -> 0.016875761 | E13: =_xlfn.COVARIANCE.S('Daily Returns'!B$4:B$2188,'Daily Returns'!E$4:E$2188)*Assumptions!$C$9 -> 0.013903987
A14: Gold | B14: =_xlfn.COVARIANCE.S('Daily Returns'!C$4:C$2188,'Daily Returns'!B$4:B$2188)*Assumptions!$C$9 -> -0.0019895533 | C14: =_xlfn.COVARIANCE.S('Daily Returns'!C$4:C$2188,'Daily Returns'!C$4:C$2188)*Assumptions!$C$9 -> 0.02368008 | D14: =_xlfn.COVARIANCE.S('Daily Returns'!C$4:C$2188,'Daily Returns'!D$4:D$2188)*Assumptions!$C$9 -> -0.0014359601 | E14: =_xlfn.COVARIANCE.S('Daily Returns'!C$4:C$2188,'Daily Returns'!E$4:E$2188)*Assumptions!$C$9 -> 0.008444378
A15: HDFC Flexi Cap | B15: =_xlfn.COVARIANCE.S('Daily Returns'!D$4:D$2188,'Daily Returns'!B$4:B$2188)*Assumptions!$C$9 -> 0.016875761 | C15: =_xlfn.COVARIANCE.S('Daily Returns'!D$4:D$2188,'Daily Returns'!C$4:C$2188)*Assumptions!$C$9 -> -0.0014359601 | D15: =_xlfn.COVARIANCE.S('Daily Returns'!D$4:D$2188,'Daily Returns'!D$4:D$2188)*Assumptions!$C$9 -> 0.044438325 | E15: =_xlfn.COVARIANCE.S('Daily Returns'!D$4:D$2188,'Daily Returns'!E$4:E$2188)*Assumptions!$C$9 -> 0.017819842
A16: Portfolio | B16: =_xlfn.COVARIANCE.S('Daily Returns'!E$4:E$2188,'Daily Returns'!B$4:B$2188)*Assumptions!$C$9 -> 0.013903987 | C16: =_xlfn.COVARIANCE.S('Daily Returns'!E$4:E$2188,'Daily Returns'!C$4:C$2188)*Assumptions!$C$9 -> 0.008444378 | D16: =_xlfn.COVARIANCE.S('Daily Returns'!E$4:E$2188,'Daily Returns'!D$4:D$2188)*Assumptions!$C$9 -> 0.017819842 | E16: =_xlfn.COVARIANCE.S('Daily Returns'!E$4:E$2188,'Daily Returns'!E$4:E$2188)*Assumptions!$C$9 -> 0.0128949
A18: Diversification Benefit
A19: Weighted-avg volatility (no diversification) | B19: =Assumptions!$C$14*(STDEV('Daily Returns'!C$4:C$2188)*SQRT(Assumptions!$C$9))+Assumptions!$C$15*(STDEV('Daily Returns'!B$4:B$2188)*SQRT(Assumptions!$C$9))+Assumptions!$C$16*(STDEV('Daily Returns'!D$4:D$2188)*SQRT(Assumptions!$C$9)) -> 0.1785637
A20: Portfolio volatility (with diversification) | B20: =(STDEV('Daily Returns'!E$4:E$2188)*SQRT(Assumptions!$C$9)) -> 0.11355571
A21: Risk removed by diversification | B21: =(Assumptions!$C$14*(STDEV('Daily Returns'!C$4:C$2188)*SQRT(Assumptions!$C$9))+Assumptions!$C$15*(STDEV('Daily Returns'!B$4:B$2188)*SQRT(Assumptions!$C$9))+Assumptions!$C$16*(STDEV('Daily Returns'!D$4:D$2188)*SQRT(Assumptions!$C$9)))-(STDEV('Daily Returns'!E$4:E$2188)*SQRT(Assumptions!$C$9)) -> 0.065007993
A22: Diversification ratio | B22: =(Assumptions!$C$14*(STDEV('Daily Returns'!C$4:C$2188)*SQRT(Assumptions!$C$9))+Assumptions!$C$15*(STDEV('Daily Returns'!B$4:B$2188)*SQRT(Assumptions!$C$9))+Assumptions!$C$16*(STDEV('Daily Returns'!D$4:D$2188)*SQRT(Assumptions!$C$9)))/(STDEV('Daily Returns'!E$4:E$2188)*SQRT(Assumptions!$C$9)) -> 1.5724766

Sheet Annual Returns
A1: Calendar-Year Returns (from daily-compounded growth)
A2: Year | B2: Sensex | C2: Gold | D2: HDFC Flexi Cap | E2: Portfolio
A3: 2015 | B3: =IFERROR(LOOKUP(2,1/('Daily Prices'!$A$3:$A$2188<DATE(2016,1,1)),'Growth Index'!B$3:B$2188)/LOOKUP(2,1/('Daily Prices'!$A$3:$A$2188<DATE(2015,1,1)),'Growth Index'!B$3:B$2188)-1,LOOKUP(2,1/('Daily Prices'!$A$3:$A$2188<DATE(2016,1,1)),'Growth Index'!B$3:B$2188)/100-1) -> -0.0505316 | C3: =IFERROR(LOOKUP(2,1/('Daily Prices'!$A$3:$A$2188<DATE(2016,1,1)),'Growth Index'!C$3:C$2188)/LOOKUP(2,1/('Daily Prices'!$A$3:$A$2188<DATE(2015,1,1)),'Growth Index'!C$3:C$2188)-1,LOOKUP(2,1/('Daily Prices'!$A$3:$A$2188<DATE(2016,1,1)),'Growth Index'!C$3:C$2188)/100-1) -> -0.077097067 | D3: =IFERROR(LOOKUP(2,1/('Daily Prices'!$A$3:$A$2188<DATE(2016,1,1)),'Growth Index'!D$3:D$2188)/LOOKUP(2,1/('Daily Prices'!$A$3:$A$2188<DATE(2015,1,1)),'Growth Index'!D$3:D$2188)-1,LOOKUP(2,1/('Daily Prices'!$A$3:$A$2188<DATE(2016,1,1)),'Growth Index'!D$3:D$2188)/100-1) -> -0.046006423 | E3: =IFERROR(LOOKUP(2,1/('Daily Prices'!$A$3:$A$2188<DATE(2016,1,1)),'Growth Index'!E$3:E$2188)/LOOKUP(2,1/('Daily Prices'!$A$3:$A$2188<DATE(2015,1,1)),'Growth Index'!E$3:E$2188)-1,LOOKUP(2,1/('Daily Prices'!$A$3:$A$2188<DATE(2016,1,1)),'Growth Index'!E$3:E$2188)/100-1) -> -0.053078177
A4: 2016 | B4: =IFERROR(LOOKUP(2,1/('Daily Prices'!$A$3:$A$2188<DATE(2017,1,1)),'Growth Index'!B$3:B$2188)/LOOKUP(2,1/('Daily Prices'!$A$3:$A$2188<DATE(2016,1,1)),'Growth Index'!B$3:B$2188)-1,LOOKUP(2,1/('Daily Prices'!$A$3:$A$2188<DATE(2017,1,1)),'Growth Index'!B$3:B$2188)/100-1) -> 0.019485756 | C4: =IFERROR(LOOKUP(2,1/('Daily Prices'!$A$3:$A$2188<DATE(2017,1,1)),'Growth Index'!C$3:C$2188)/LOOKUP(2,1/('Daily Prices'!$A$3:$A$2188<DATE(2016,1,1)),'Growth Index'!C$3:C$2188)-1,LOOKUP(2,1/('Daily Prices'!$A$3:$A$2188<DATE(2017,1,1)),'Growth Index'!C$3:C$2188)/100-1) -> 0.10547275 | D4: =IFERROR(LOOKUP(2,1/('Daily Prices'!$A$3:$A$2188<DATE(2017,1,1)),'Growth Index'!D$3:D$2188)/LOOKUP(2,1/('Daily Prices'!$A$3:$A$2188<DATE(2016,1,1)),'Growth Index'!D$3:D$2188)-1,LOOKUP(2,1/('Daily Prices'!$A$3:$A$2188<DATE(2017,1,1)),'Growth Index'!D$3:D$2188)/100-1) -> 0.081613209 | E4: =IFERROR(LOOKUP(2,1/('Daily Prices'!$A$3:$A$2188<DATE(2017,1,1)),'Growth Index'!E$3:E$2188)/LOOKUP(2,1/('Daily Prices'!$A$3:$A$2188<DATE(2016,1,1)),'Growth Index'!E$3:E$2188)-1,LOOKUP(2,1/('Daily Prices'!$A$3:$A$2188<DATE(2017,1,1)),'Growth Index'!E$3:E$2188)/100-1) -> 0.082866022
A5: 2017 | B5: =IFERROR(LOOKUP(2,1/('Daily Prices'!$A$3:$A$2188<DATE(2018,1,1)),'Growth Index'!B$3:B$2188)/LOOKUP(2,1/('Daily Prices'!$A$3:$A$2188<DATE(2017,1,1)),'Growth Index'!B$3:B$2188)-1,LOOKUP(2,1/('Daily Prices'!$A$3:$A$2188<DATE(2018,1,1)),'Growth Index'!B$3:B$2188)/100-1) -> 0.27905963 | C5: =IFERROR(LOOKUP(2,1/('Daily Prices'!$A$3:$A$2188<DATE(2018,1,1)),'Growth Index'!C$3:C$2188)/LOOKUP(2,1/('Daily Prices'!$A$3:$A$2188<DATE(2017,1,1)),'Growth Index'!C$3:C$2188)-1,LOOKUP(2,1/('Daily Prices'!$A$3:$A$2188<DATE(2018,1,1)),'Growth Index'!C$3:C$2188)/100-1) -> 0.061998077 | D5: =IFERROR(LOOKUP(2,1/('Daily Prices'!$A$3:$A$2188<DATE(2018,1,1)),'Growth Index'!D$3:D$2188)/LOOKUP(2,1/('Daily Prices'!$A$3:$A$2188<DATE(2017,1,1)),'Growth Index'!D$3:D$2188)-1,LOOKUP(2,1/('Daily Prices'!$A$3:$A$2188<DATE(2018,1,1)),'Growth Index'!D$3:D$2188)/100-1) -> 0.38046724 | E5: =IFERROR(LOOKUP(2,1/('Daily Prices'!$A$3:$A$2188<DATE(2018,1,1)),'Growth Index'!E$3:E$2188)/LOOKUP(2,1/('Daily Prices'!$A$3:$A$2188<DATE(2017,1,1)),'Growth Index'!E$3:E$2188)-1,LOOKUP(2,1/('Daily Prices'!$A$3:$A$2188<DATE(2018,1,1)),'Growth Index'!E$3:E$2188)/100-1) -> 0.220447
A6: 2018 | B6: =IFERROR(LOOKUP(2,1/('Daily Prices'!$A$3:$A$2188<DATE(2019,1,1)),'Growth Index'!B$3:B$2188)/LOOKUP(2,1/('Daily Prices'!$A$3:$A$2188<DATE(2018,1,1)),'Growth Index'!B$3:B$2188)-1,LOOKUP(2,1/('Daily Prices'!$A$3:$A$2188<DATE(2019,1,1)),'Growth Index'!B$3:B$2188)/100-1) -> 0.059063043 | C6: =IFERROR(LOOKUP(2,1/('Daily Prices'!$A$3:$A$2188<DATE(2019,1,1)),'Growth Index'!C$3:C$2188)/LOOKUP(2,1/('Daily Prices'!$A$3:$A$2188<DATE(2018,1,1)),'Growth Index'!C$3:C$2188)-1,LOOKUP(2,1/('Daily Prices'!$A$3:$A$2188<DATE(2019,1,1)),'Growth Index'!C$3:C$2188)/100-1) -> 0.081192236 | D6: =IFERROR(LOOKUP(2,1/('Daily Prices'!$A$3:$A$2188<DATE(2019,1,1)),'Growth Index'!D$3:D$2188)/LOOKUP(2,1/('Daily Prices'!$A$3:$A$2188<DATE(2018,1,1)),'Growth Index'!D$3:D$2188)-1,LOOKUP(2,1/('Daily Prices'!$A$3:$A$2188<DATE(2019,1,1)),'Growth Index'!D$3:D$2188)/100-1) -> -0.026244201 | E6: =IFERROR(LOOKUP(2,1/('Daily Prices'!$A$3:$A$2188<DATE(2019,1,1)),'Growth Index'!E$3:E$2188)/LOOKUP(2,1/('Daily Prices'!$A$3:$A$2188<DATE(2018,1,1)),'Growth Index'!E$3:E$2188)-1,LOOKUP(2,1/('Daily Prices'!$A$3:$A$2188<DATE(2019,1,1)),'Growth Index'!E$3:E$2188)/100-1) -> 0.049746136
A7: 2019 | B7: =IFERROR(LOOKUP(2,1/('Daily Prices'!$A$3:$A$2188<DATE(2020,1,1)),'Growth Index'!B$3:B$2188)/LOOKUP(2,1/('Daily Prices'!$A$3:$A$2188<DATE(2019,1,1)),'Growth Index'!B$3:B$2188)-1,LOOKUP(2,1/('Daily Prices'!$A$3:$A$2188<DATE(2020,1,1)),'Growth Index'!B$3:B$2188)/100-1) -> 0.14376629 | C7: =IFERROR(LOOKUP(2,1/('Daily Prices'!$A$3:$A$2188<DATE(2020,1,1)),'Growth Index'!C$3:C$2188)/LOOKUP(2,1/('Daily Prices'!$A$3:$A$2188<DATE(2019,1,1)),'Growth Index'!C$3:C$2188)-1,LOOKUP(2,1/('Daily Prices'!$A$3:$A$2188<DATE(2020,1,1)),'Growth Index'!C$3:C$2188)/100-1) -> 0.20766113 | D7: =IFERROR(LOOKUP(2,1/('Daily Prices'!$A$3:$A$2188<DATE(2020,1,1)),'Growth Index'!D$3:D$2188)/LOOKUP(2,1/('Daily Prices'!$A$3:$A$2188<DATE(2019,1,1)),'Growth Index'!D$3:D$2188)-1,LOOKUP(2,1/('Daily Prices'!$A$3:$A$2188<DATE(2020,1,1)),'Growth Index'!D$3:D$2188)/100-1) -> 0.074331963 | E7: =IFERROR(LOOKUP(2,1/('Daily Prices'!$A$3:$A$2188<DATE(2020,1,1)),'Growth Index'!E$3:E$2188)/LOOKUP(2,1/('Daily Prices'!$A$3:$A$2188<DATE(2019,1,1)),'Growth Index'!E$3:E$2188)-1,LOOKUP(2,1/('Daily Prices'!$A$3:$A$2188<DATE(2020,1,1)),'Growth Index'!E$3:E$2188)/100-1) -> 0.15674905
A8: 2020 | B8: =IFERROR(LOOKUP(2,1/('Daily Prices'!$A$3:$A$2188<DATE(2021,1,1)),'Growth Index'!B$3:B$2188)/LOOKUP(2,1/('Daily Prices'!$A$3:$A$2188<DATE(2020,1,1)),'Growth Index'!B$3:B$2188)-1,LOOKUP(2,1/('Daily Prices'!$A$3:$A$2188<DATE(2021,1,1)),'Growth Index'!B$3:B$2188)/100-1) -> 0.15750305 | C8: =IFERROR(LOOKUP(2,1/('Daily Prices'!$A$3:$A$2188<DATE(2021,1,1)),'Growth Index'!C$3:C$2188)/LOOKUP(2,1/('Daily Prices'!$A$3:$A$2188<DATE(2020,1,1)),'Growth Index'!C$3:C$2188)-1,LOOKUP(2,1/('Daily Prices'!$A$3:$A$2188<DATE(2021,1,1)),'Growth Index'!C$3:C$2188)/100-1) -> 0.27914834 | D8: =IFERROR(LOOKUP(2,1/('Daily Prices'!$A$3:$A$2188<DATE(2021,1,1)),'Growth Index'!D$3:D$2188)/LOOKUP(2,1/('Daily Prices'!$A$3:$A$2188<DATE(2020,1,1)),'Growth Index'!D$3:D$2188)-1,LOOKUP(2,1/('Daily Prices'!$A$3:$A$2188<DATE(2021,1,1)),'Growth Index'!D$3:D$2188)/100-1) -> 0.070465251 | E8: =IFERROR(LOOKUP(2,1/('Daily Prices'!$A$3:$A$2188<DATE(2021,1,1)),'Growth Index'!E$3:E$2188)/LOOKUP(2,1/('Daily Prices'!$A$3:$A$2188<DATE(2020,1,1)),'Growth Index'!E$3:E$2188)-1,LOOKUP(2,1/('Daily Prices'!$A$3:$A$2188<DATE(2021,1,1)),'Growth Index'!E$3:E$2188)/100-1) -> 0.19649512
A9: 2021 | B9: =IFERROR(LOOKUP(2,1/('Daily Prices'!$A$3:$A$2188<DATE(2022,1,1)),'Growth Index'!B$3:B$2188)/LOOKUP(2,1/('Daily Prices'!$A$3:$A$2188<DATE(2021,1,1)),'Growth Index'!B$3:B$2188)-1,LOOKUP(2,1/('Daily Prices'!$A$3:$A$2188<DATE(2022,1,1)),'Growth Index'!B$3:B$2188)/100-1) -> 0.21994131 | C9: =IFERROR(LOOKUP(2,1/('Daily Prices'!$A$3:$A$2188<DATE(2022,1,1)),'Growth Index'!C$3:C$2188)/LOOKUP(2,1/('Daily Prices'!$A$3:$A$2188<DATE(2021,1,1)),'Growth Index'!C$3:C$2188)-1,LOOKUP(2,1/('Daily Prices'!$A$3:$A$2188<DATE(2022,1,1)),'Growth Index'!C$3:C$2188)/100-1) -> -0.02628293 | D9: =IFERROR(LOOKUP(2,1/('Daily Prices'!$A$3:$A$2188<DATE(2022,1,1)),'Growth Index'!D$3:D$2188)/LOOKUP(2,1/('Daily Prices'!$A$3:$A$2188<DATE(2021,1,1)),'Growth Index'!D$3:D$2188)-1,LOOKUP(2,1/('Daily Prices'!$A$3:$A$2188<DATE(2022,1,1)),'Growth Index'!D$3:D$2188)/100-1) -> 0.36996838 | E9: =IFERROR(LOOKUP(2,1/('Daily Prices'!$A$3:$A$2188<DATE(2022,1,1)),'Growth Index'!E$3:E$2188)/LOOKUP(2,1/('Daily Prices'!$A$3:$A$2188<DATE(2021,1,1)),'Growth Index'!E$3:E$2188)-1,LOOKUP(2,1/('Daily Prices'!$A$3:$A$2188<DATE(2022,1,1)),'Growth Index'!E$3:E$2188)/100-1) -> 0.16448467
A10: 2022 | B10: =IFERROR(LOOKUP(2,1/('Daily Prices'!$A$3:$A$2188<DATE(2023,1,1)),'Growth Index'!B$3:B$2188)/LOOKUP(2,1/('Daily Prices'!$A$3:$A$2188<DATE(2022,1,1)),'Growth Index'!B$3:B$2188)-1,LOOKUP(2,1/('Daily Prices'!$A$3:$A$2188<DATE(2023,1,1)),'Growth Index'!B$3:B$2188)/100-1) -> 0.044407732 | C10: =IFERROR(LOOKUP(2,1/('Daily Prices'!$A$3:$A$2188<DATE(2023,1,1)),'Growth Index'!C$3:C$2188)/LOOKUP(2,1/('Daily Prices'!$A$3:$A$2188<DATE(2022,1,1)),'Growth Index'!C$3:C$2188)-1,LOOKUP(2,1/('Daily Prices'!$A$3:$A$2188<DATE(2023,1,1)),'Growth Index'!C$3:C$2188)/100-1) -> 0.11710848 | D10: =IFERROR(LOOKUP(2,1/('Daily Prices'!$A$3:$A$2188<DATE(2023,1,1)),'Growth Index'!D$3:D$2188)/LOOKUP(2,1/('Daily Prices'!$A$3:$A$2188<DATE(2022,1,1)),'Growth Index'!D$3:D$2188)-1,LOOKUP(2,1/('Daily Prices'!$A$3:$A$2188<DATE(2023,1,1)),'Growth Index'!D$3:D$2188)/100-1) -> 0.19086224 | E10: =IFERROR(LOOKUP(2,1/('Daily Prices'!$A$3:$A$2188<DATE(2023,1,1)),'Growth Index'!E$3:E$2188)/LOOKUP(2,1/('Daily Prices'!$A$3:$A$2188<DATE(2022,1,1)),'Growth Index'!E$3:E$2188)-1,LOOKUP(2,1/('Daily Prices'!$A$3:$A$2188<DATE(2023,1,1)),'Growth Index'!E$3:E$2188)/100-1) -> 0.12693263
A11: 2023 | B11: =IFERROR(LOOKUP(2,1/('Daily Prices'!$A$3:$A$2188<DATE(2024,1,1)),'Growth Index'!B$3:B$2188)/LOOKUP(2,1/('Daily Prices'!$A$3:$A$2188<DATE(2023,1,1)),'Growth Index'!B$3:B$2188)-1,LOOKUP(2,1/('Daily Prices'!$A$3:$A$2188<DATE(2024,1,1)),'Growth Index'!B$3:B$2188)/100-1) -> 0.18736656 | C11: =IFERROR(LOOKUP(2,1/('Daily Prices'!$A$3:$A$2188<DATE(2024,1,1)),'Growth Index'!C$3:C$2188)/LOOKUP(2,1/('Daily Prices'!$A$3:$A$2188<DATE(2023,1,1)),'Growth Index'!C$3:C$2188)-1,LOOKUP(2,1/('Daily Prices'!$A$3:$A$2188<DATE(2024,1,1)),'Growth Index'!C$3:C$2188)/100-1) -> 0.1506805 | D11: =IFERROR(LOOKUP(2,1/('Daily Prices'!$A$3:$A$2188<DATE(2024,1,1)),'Growth Index'!D$3:D$2188)/LOOKUP(2,1/('Daily Prices'!$A$3:$A$2188<DATE(2023,1,1)),'Growth Index'!D$3:D$2188)-1,LOOKUP(2,1/('Daily Prices'!$A$3:$A$2188<DATE(2024,1,1)),'Growth Index'!D$3:D$2188)/100-1) -> 0.31452654 | E11: =IFERROR(LOOKUP(2,1/('Daily Prices'!$A$3:$A$2188<DATE(2024,1,1)),'Growth Index'!E$3:E$2188)/LOOKUP(2,1/('Daily Prices'!$A$3:$A$2188<DATE(2023,1,1)),'Growth Index'!E$3:E$2188)-1,LOOKUP(2,1/('Daily Prices'!$A$3:$A$2188<DATE(2024,1,1)),'Growth Index'!E$3:E$2188)/100-1) -> 0.21553019
A12: 2024 | B12: =IFERROR(LOOKUP(2,1/('Daily Prices'!$A$3:$A$2188<DATE(2025,1,1)),'Growth Index'!B$3:B$2188)/LOOKUP(2,1/('Daily Prices'!$A$3:$A$2188<DATE(2024,1,1)),'Growth Index'!B$3:B$2188)-1,LOOKUP(2,1/('Daily Prices'!$A$3:$A$2188<DATE(2025,1,1)),'Growth Index'!B$3:B$2188)/100-1) -> 0.081654606 | C12: =IFERROR(LOOKUP(2,1/('Daily Prices'!$A$3:$A$2188<DATE(2025,1,1)),'Growth Index'!C$3:C$2188)/LOOKUP(2,1/('Daily Prices'!$A$3:$A$2188<DATE(2024,1,1)),'Growth Index'!C$3:C$2188)-1,LOOKUP(2,1/('Daily Prices'!$A$3:$A$2188<DATE(2025,1,1)),'Growth Index'!C$3:C$2188)/100-1) -> 0.29024972 | D12: =IFERROR(LOOKUP(2,1/('Daily Prices'!$A$3:$A$2188<DATE(2025,1,1)),'Growth Index'!D$3:D$2188)/LOOKUP(2,1/('Daily Prices'!$A$3:$A$2188<DATE(2024,1,1)),'Growth Index'!D$3:D$2188)-1,LOOKUP(2,1/('Daily Prices'!$A$3:$A$2188<DATE(2025,1,1)),'Growth Index'!D$3:D$2188)/100-1) -> 0.24326503 | E12: =IFERROR(LOOKUP(2,1/('Daily Prices'!$A$3:$A$2188<DATE(2025,1,1)),'Growth Index'!E$3:E$2188)/LOOKUP(2,1/('Daily Prices'!$A$3:$A$2188<DATE(2024,1,1)),'Growth Index'!E$3:E$2188)-1,LOOKUP(2,1/('Daily Prices'!$A$3:$A$2188<DATE(2025,1,1)),'Growth Index'!E$3:E$2188)/100-1) -> 0.21688756
A13: CAGR | B13: =('Growth Index'!B$2188/'Growth Index'!B$3)^(365.25/('Daily Prices'!$A$2188-'Daily Prices'!$A$3))-1 -> 0.1100635 | C13: =('Growth Index'!C$2188/'Growth Index'!C$3)^(365.25/('Daily Prices'!$A$2188-'Daily Prices'!$A$3))-1 -> 0.11322183 | D13: =('Growth Index'!D$2188/'Growth Index'!D$3)^(365.25/('Daily Prices'!$A$2188-'Daily Prices'!$A$3))-1 -> 0.15579175 | E13: =('Growth Index'!E$2188/'Growth Index'!E$3)^(365.25/('Daily Prices'!$A$2188-'Daily Prices'!$A$3))-1 -> 0.13442687

Sheet Monthly Returns
A1: Monthly Returns — seasonality heatmap (one block per asset)
A3: Sensex
A4: Year | B4: Jan | C4: Feb | D4: Mar | E4: Apr | F4: May | G4: Jun | H4: Jul | I4: Aug | J4: Sep | K4: Oct | L4: Nov | M4: Dec | N4: Year
A5: 2015 | B5: =IFERROR(LOOKUP(2,1/('Daily Prices'!$A$3:$A$2188<DATE(2015,2,1)+0),'Growth Index'!B$3:B$2188)/LOOKUP(2,1/('Daily Prices'!$A$3:$A$2188<DATE(2015,1,1)),'Growth Index'!B$3:B$2188)-1,LOOKUP(2,1/('Daily Prices'!$A$3:$A$2188<DATE(2015,2,1)+0),'Growth Index'!B$3:B$2188)/100-1) -> 0.0609073 | C5: =IFERROR(LOOKUP(2,1/('Daily Prices'!$A$3:$A$2188<DATE(2015,3,1)+0),'Growth Index'!B$3:B$2188)/LOOKUP(2,1/('Daily Prices'!$A$3:$A$2188<DATE(2015,2,1)),'Growth Index'!B$3:B$2188)-1,LOOKUP(2,1/('Daily Prices'!$A$3:$A$2188<DATE(2015,3,1)+0),'Growth Index'!B$3:B$2188)/100-1) -> 0.0012736889 | D5: =IFERROR(LOOKUP(2,1/('Daily Prices'!$A$3:$A$2188<DATE(2015,4,1)+0),'Growth Index'!B$3:B$2188)/LOOKUP(2,1/('Daily Prices'!$A$3:$A$2188<DATE(2015,3,1)),'Growth Index'!B$3:B$2188)-1,LOOKUP(2,1/('Daily Prices'!$A$3:$A$2188<DATE(2015,4,1)+0),'Growth Index'!B$3:B$2188)/100-1) -> -0.043210979 | E5: =IFERROR(LOOKUP(2,1/('Daily Prices'!$A$3:$A$2188<DATE(2015,5,1)+0),'Growth Index'!B$3:B$2188)/LOOKUP(2,1/('Daily Prices'!$A$3:$A$2188<DATE(2015,4,1)),'Growth Index'!B$3:B$2188)-1,LOOKUP(2,1/('Daily Prices'!$A$3:$A$2188<DATE(2015,5,1)+0),'Growth Index'!B$3:B$2188)/100-1) -> -0.033843525 | F5: =IFERROR(LOOKUP(2,1/('Daily Prices'!$A$3:$A$2188<DATE(2015,6,1)+0),'Growth Index'!B$3:B$2188)/LOOKUP(2,1/('Daily Prices'!$A$3:$A$2188<DATE(2015,5,1)),'Growth Index'!B$3:B$2188)-1,LOOKUP(2,1/('Daily Prices'!$A$3:$A$2188<DATE(2015,6,1)+0),'Growth Index'!B$3:B$2188)/100-1) -> 0.030251402 | G5: =IFERROR(LOOKUP(2,1/('Daily Prices'!$A$3:$A$2188<DATE(2015,7,1)+0),'Growth Index'!B$3:B$2188)/LOOKUP(2,1/('Daily Prices'!$A$3:$A$2188<DATE(2015,6,1)),'Growth Index'!B$3:B$2188)-1,LOOKUP(2,1/('Daily Prices'!$A$3:$A$2188<DATE(2015,7,1)+0),'Growth Index'!B$3:B$2188)/100-1) -> -0.0017108397 | H5: =IFERROR(LOOKUP(2,1/('Daily Prices'!$A$3:$A$2188<DATE(2015,8,1)+0),'Growth Index'!B$3:B$2188)/LOOKUP(2,1/('Daily Prices'!$A$3:$A$2188<DATE(2015,7,1)),'Growth Index'!B$3:B$2188)-1,LOOKUP(2,1/('Daily Prices'!$A$3:$A$2188<DATE(2015,8,1)+0),'Growth Index'!B$3:B$2188)/100-1) -> 0.01201296 | I5: =IFERROR(LOOKUP(2,1/('Daily Prices'!$A$3:$A$2188<DATE(2015,9,1)+0),'Growth Index'!B$3:B$2188)/LOOKUP(2,1/('Daily Prices'!$A$3:$A$2188<DATE(2015,8,1)),'Growth Index'!B$3:B$2188)-1,LOOKUP(2,1/('Daily Prices'!$A$3:$A$2188<DATE(2015,9,1)+0),'Growth Index'!B$3:B$2188)/100-1) -> -0.065143114 | J5: =IFERROR(LOOKUP(2,1/('Daily Prices'!$A$3:$A$2188<DATE(2015,10,1)+0),'Growth Index'!B$3:B$2188)/LOOKUP(2,1/('Daily Prices'!$A$3:$A$2188<DATE(2015,9,1)),'Growth Index'!B$3:B$2188)-1,LOOKUP(2,1/('Daily Prices'!$A$3:$A$2188<DATE(2015,10,1)+0),'Growth Index'!B$3:B$2188)/100-1) -> -0.0048799437 | K5: =IFERROR(LOOKUP(2,1/('Daily Prices'!$A$3:$A$2188<DATE(2015,11,1)+0),'Growth Index'!B$3:B$2188)/LOOKUP(2,1/('Daily Prices'!$A$3:$A$2188<DATE(2015,10,1)),'Growth Index'!B$3:B$2188)-1,LOOKUP(2,1/('Daily Prices'!$A$3:$A$2188<DATE(2015,11,1)+0),'Growth Index'!B$3:B$2188)/100-1) -> 0.019193396 | L5: =IFERROR(LOOKUP(2,1/('Daily Prices'!$A$3:$A$2188<DATE(2015,12,1)+0),'Growth Index'!B$3:B$2188)/LOOKUP(2,1/('Daily Prices'!$A$3:$A$2188<DATE(2015,11,1)),'Growth Index'!B$3:B$2188)-1,LOOKUP(2,1/('Daily Prices'!$A$3:$A$2188<DATE(2015,12,1)+0),'Growth Index'!B$3:B$2188)/100-1) -> -0.019175573 | M5: =IFERROR(LOOKUP(2,1/('Daily Prices'!$A$3:$A$2188<DATE(2016,1,1)),'Growth Index'!B$3:B$2188)/LOOKUP(2,1/('Daily Prices'!$A$3:$A$2188<DATE(2015,12,1)),'Growth Index'!B$3:B$2188)-1,LOOKUP(2,1/('Daily Prices'!$A$3:$A$2188<DATE(2016,1,1)),'Growth Index'!B$3:B$2188)/100-1) -> -0.0010758952 | N5: =IFERROR(LOOKUP(2,1/('Daily Prices'!$A$3:$A$2188<DATE(2016,1,1)),'Growth Index'!B$3:B$2188)/LOOKUP(2,1/('Daily Prices'!$A$3:$A$2188<DATE(2015,1,1)),'Growth Index'!B$3:B$2188)-1,LOOKUP(2,1/('Daily Prices'!$A$3:$A$2188<DATE(2016,1,1)),'Growth Index'!B$3:B$2188)/100-1) -> -0.0505316
A6: 2016 | B6: =IFERROR(LOOKUP(2,1/('Daily Prices'!$A$3:$A$2188<DATE(2016,2,1)+0),'Growth Index'!B$3:B$2188)/LOOKUP(2,1/('Daily Prices'!$A$3:$A$2188<DATE(2016,1,1)),'Growth Index'!B$3:B$2188)-1,LOOKUP(2,1/('Daily Prices'!$A$3:$A$2188<DATE(2016,2,1)+0),'Growth Index'!B$3:B$2188)/100-1) -> -0.047739948 | C6: =IFERROR(LOOKUP(2,1/('Daily Prices'!$A$3:$A$2188<DATE(2016,3,1)+0),'Growth Index'!B$3:B$2188)/LOOKUP(2,1/('Daily Prices'!$A$3:$A$2188<DATE(2016,2,1)),'Growth Index'!B$3:B$2188)-1,LOOKUP(2,1/('Daily Prices'!$A$3:$A$2188<DATE(2016,3,1)+0),'Growth Index'!B$3:B$2188)/100-1) -> -0.075136235 | D6: =IFERROR(LOOKUP(2,1/('Daily Prices'!$A$3:$A$2188<DATE(2016,4,1)+0),'Growth Index'!B$3:B$2188)/LOOKUP(2,1/('Daily Prices'!$A$3:$A$2188<DATE(2016,3,1)),'Growth Index'!B$3:B$2188)-1,LOOKUP(2,1/('Daily Prices'!$A$3:$A$2188<DATE(2016,4,1)+0),'Growth Index'!B$3:B$2188)/100-1) -> 0.1017242 | E6: =IFERROR(LOOKUP(2,1/('Daily Prices'!$A$3:$A$2188<DATE(2016,5,1)+0),'Growth Index'!B$3:B$2188)/LOOKUP(2,1/('Daily Prices'!$A$3:$A$2188<DATE(2016,4,1)),'Growth Index'!B$3:B$2188)-1,LOOKUP(2,1/('Daily Prices'!$A$3:$A$2188<DATE(2016,5,1)+0),'Growth Index'!B$3:B$2188)/100-1) -> 0.010447536 | F6: =IFERROR(LOOKUP(2,1/('Daily Prices'!$A$3:$A$2188<DATE(2016,6,1)+0),'Growth Index'!B$3:B$2188)/LOOKUP(2,1/('Daily Prices'!$A$3:$A$2188<DATE(2016,5,1)),'Growth Index'!B$3:B$2188)-1,LOOKUP(2,1/('Daily Prices'!$A$3:$A$2188<DATE(2016,6,1)+0),'Growth Index'!B$3:B$2188)/100-1) -> 0.041447876 | G6: =IFERROR(LOOKUP(2,1/('Daily Prices'!$A$3:$A$2188<DATE(2016,7,1)+0),'Growth Index'!B$3:B$2188)/LOOKUP(2,1/('Daily Prices'!$A$3:$A$2188<DATE(2016,6,1)),'Growth Index'!B$3:B$2188)-1,LOOKUP(2,1/('Daily Prices'!$A$3:$A$2188<DATE(2016,7,1)+0),'Growth Index'!B$3:B$2188)/100-1) -> 0.012440397 | H6: =IFERROR(LOOKUP(2,1/('Daily Prices'!$A$3:$A$2188<DATE(2016,8,1)+0),'Growth Index'!B$3:B$2188)/LOOKUP(2,1/('Daily Prices'!$A$3:$A$2188<DATE(2016,7,1)),'Growth Index'!B$3:B$2188)-1,LOOKUP(2,1/('Daily Prices'!$A$3:$A$2188<DATE(2016,8,1)+0),'Growth Index'!B$3:B$2188)/100-1) -> 0.038968552 | I6: =IFERROR(LOOKUP(2,1/('Daily Prices'!$A$3:$A$2188<DATE(2016,9,1)+0),'Growth Index'!B$3:B$2188)/LOOKUP(2,1/('Daily Prices'!$A$3:$A$2188<DATE(2016,8,1)),'Growth Index'!B$3:B$2188)-1,LOOKUP(2,1/('Daily Prices'!$A$3:$A$2188<DATE(2016,9,1)+0),'Growth Index'!B$3:B$2188)/100-1) -> 0.014270355 | J6: =IFERROR(LOOKUP(2,1/('Daily Prices'!$A$3:$A$2188<DATE(2016,10,1)+0),'Growth Index'!B$3:B$2188)/LOOKUP(2,1/('Daily Prices'!$A$3:$A$2188<DATE(2016,9,1)),'Growth Index'!B$3:B$2188)-1,LOOKUP(2,1/('Daily Prices'!$A$3:$A$2188<DATE(2016,10,1)+0),'Growth Index'!B$3:B$2188)/100-1) -> -0.020603349 | K6: =IFERROR(LOOKUP(2,1/('Daily Prices'!$A$3:$A$2188<DATE(2016,11,1)+0),'Growth Index'!B$3:B$2188)/LOOKUP(2,1/('Daily Prices'!$A$3:$A$2188<DATE(2016,10,1)),'Growth Index'!B$3:B$2188)-1,LOOKUP(2,1/('Daily Prices'!$A$3:$A$2188<DATE(2016,11,1)+0),'Growth Index'!B$3:B$2188)/100-1) -> 0.0027111932 | L6: =IFERROR(LOOKUP(2,1/('Daily Prices'!$A$3:$A$2188<DATE(2016,12,1)+0),'Growth Index'!B$3:B$2188)/LOOKUP(2,1/('Daily Prices'!$A$3:$A$2188<DATE(2016,11,1)),'Growth Index'!B$3:B$2188)-1,LOOKUP(2,1/('Daily Prices'!$A$3:$A$2188<DATE(2016,12,1)+0),'Growth Index'!B$3:B$2188)/100-1) -> -0.046121344 | M6: =IFERROR(LOOKUP(2,1/('Daily Prices'!$A$3:$A$2188<DATE(2017,1,1)),'Growth Index'!B$3:B$2188)/LOOKUP(2,1/('Daily Prices'!$A$3:$A$2188<DATE(2016,12,1)),'Growth Index'!B$3:B$2188)-1,LOOKUP(2,1/('Daily Prices'!$A$3:$A$2188<DATE(2017,1,1)),'Growth Index'!B$3:B$2188)/100-1) -> -0.00098863872 | N6: =IFERROR(LOOKUP(2,1/('Daily Prices'!$A$3:$A$2188<DATE(2017,1,1)),'Growth Index'!B$3:B$2188)/LOOKUP(2,1/('Daily Prices'!$A$3:$A$2188<DATE(2016,1,1)),'Growth Index'!B$3:B$2188)-1,LOOKUP(2,1/('Daily Prices'!$A$3:$A$2188<DATE(2017,1,1)),'Growth Index'!B$3:B$2188)/100-1) -> 0.019485756
A7: 2017 | B7: =IFERROR(LOOKUP(2,1/('Daily Prices'!$A$3:$A$2188<DATE(2017,2,1)+0),'Growth Index'!B$3:B$2188)/LOOKUP(2,1/('Daily Prices'!$A$3:$A$2188<DATE(2017,1,1)),'Growth Index'!B$3:B$2188)-1,LOOKUP(2,1/('Daily Prices'!$A$3:$A$2188<DATE(2017,2,1)+0),'Growth Index'!B$3:B$2188)/100-1) -> 0.038664546 | C7: =IFERROR(LOOKUP(2,1/('Daily Prices'!$A$3:$A$2188<DATE(2017,3,1)+0),'Growth Index'!B$3:B$2188)/LOOKUP(2,1/('Daily Prices'!$A$3:$A$2188<DATE(2017,2,1)),'Growth Index'!B$3:B$2188)-1,LOOKUP(2,1/('Daily Prices'!$A$3:$A$2188<DATE(2017,3,1)+0),'Growth Index'!B$3:B$2188)/100-1) -> 0.039317384 | D7: =IFERROR(LOOKUP(2,1/('Daily Prices'!$A$3:$A$2188<DATE(2017,4,1)+0),'Growth Index'!B$3:B$2188)/LOOKUP(2,1/('Daily Prices'!$A$3:$A$2188<DATE(2017,3,1)),'Growth Index'!B$3:B$2188)-1,LOOKUP(2,1/('Daily Prices'!$A$3:$A$2188<DATE(2017,4,1)+0),'Growth Index'!B$3:B$2188)/100-1) -> 0.030517699 | E7: =IFERROR(LOOKUP(2,1/('Daily Prices'!$A$3:$A$2188<DATE(2017,5,1)+0),'Growth Index'!B$3:B$2188)/LOOKUP(2,1/('Daily Prices'!$A$3:$A$2188<DATE(2017,4,1)),'Growth Index'!B$3:B$2188)-1,LOOKUP(2,1/('Daily Prices'!$A$3:$A$2188<DATE(2017,5,1)+0),'Growth Index'!B$3:B$2188)/100-1) -> 0.010057224 | F7: =IFERROR(LOOKUP(2,1/('Daily Prices'!$A$3:$A$2188<DATE(2017,6,1)+0),'Growth Index'!B$3:B$2188)/LOOKUP(2,1/('Daily Prices'!$A$3:$A$2188<DATE(2017,5,1)),'Growth Index'!B$3:B$2188)-1,LOOKUP(2,1/('Daily Prices'!$A$3:$A$2188<DATE(2017,6,1)+0),'Growth Index'!B$3:B$2188)/100-1) -> 0.041024921 | G7: =IFERROR(LOOKUP(2,1/('Daily Prices'!$A$3:$A$2188<DATE(2017,7,1)+0),'Growth Index'!B$3:B$2188)/LOOKUP(2,1/('Daily Prices'!$A$3:$A$2188<DATE(2017,6,1)),'Growth Index'!B$3:B$2188)-1,LOOKUP(2,1/('Daily Prices'!$A$3:$A$2188<DATE(2017,7,1)+0),'Growth Index'!B$3:B$2188)/100-1) -> -0.0071980813 | H7: =IFERROR(LOOKUP(2,1/('Daily Prices'!$A$3:$A$2188<DATE(2017,8,1)+0),'Growth Index'!B$3:B$2188)/LOOKUP(2,1/('Daily Prices'!$A$3:$A$2188<DATE(2017,7,1)),'Growth Index'!B$3:B$2188)-1,LOOKUP(2,1/('Daily Prices'!$A$3:$A$2188<DATE(2017,8,1)+0),'Growth Index'!B$3:B$2188)/100-1) -> 0.051528041 | I7: =IFERROR(LOOKUP(2,1/('Daily Prices'!$A$3:$A$2188<DATE(2017,9,1)+0),'Growth Index'!B$3:B$2188)/LOOKUP(2,1/('Daily Prices'!$A$3:$A$2188<DATE(2017,8,1)),'Growth Index'!B$3:B$2188)-1,LOOKUP(2,1/('Daily Prices'!$A$3:$A$2188<DATE(2017,9,1)+0),'Growth Index'!B$3:B$2188)/100-1) -> -0.024125833 | J7: =IFERROR(LOOKUP(2,1/('Daily Prices'!$A$3:$A$2188<DATE(2017,10,1)+0),'Growth Index'!B$3:B$2188)/LOOKUP(2,1/('Daily Prices'!$A$3:$A$2188<DATE(2017,9,1)),'Growth Index'!B$3:B$2188)-1,LOOKUP(2,1/('Daily Prices'!$A$3:$A$2188<DATE(2017,10,1)+0),'Growth Index'!B$3:B$2188)/100-1) -> -0.014080148 | K7: =IFERROR(LOOKUP(2,1/('Daily Prices'!$A$3:$A$2188<DATE(2017,11,1)+0),'Growth Index'!B$3:B$2188)/LOOKUP(2,1/('Daily Prices'!$A$3:$A$2188<DATE(2017,10,1)),'Growth Index'!B$3:B$2188)-1,LOOKUP(2,1/('Daily Prices'!$A$3:$A$2188<DATE(2017,11,1)+0),'Growth Index'!B$3:B$2188)/100-1) -> 0.061674571 | L7: =IFERROR(LOOKUP(2,1/('Daily Prices'!$A$3:$A$2188<DATE(2017,12,1)+0),'Growth Index'!B$3:B$2188)/LOOKUP(2,1/('Daily Prices'!$A$3:$A$2188<DATE(2017,11,1)),'Growth Index'!B$3:B$2188)-1,LOOKUP(2,1/('Daily Prices'!$A$3:$A$2188<DATE(2017,12,1)+0),'Growth Index'!B$3:B$2188)/100-1) -> -0.0019203249 | M7: =IFERROR(LOOKUP(2,1/('Daily Prices'!$A$3:$A$2188<DATE(2018,1,1)),'Growth Index'!B$3:B$2188)/LOOKUP(2,1/('Daily Prices'!$A$3:$A$2188<DATE(2017,12,1)),'Growth Index'!B$3:B$2188)-1,LOOKUP(2,1/('Daily Prices'!$A$3:$A$2188<DATE(2018,1,1)),'Growth Index'!B$3:B$2188)/100-1) -> 0.027375499 | N7: =IFERROR(LOOKUP(2,1/('Daily Prices'!$A$3:$A$2188<DATE(2018,1,1)),'Growth Index'!B$3:B$2188)/LOOKUP(2,1/('Daily Prices'!$A$3:$A$2188<DATE(2017,1,1)),'Growth Index'!B$3:B$2188)-1,LOOKUP(2,1/('Daily Prices'!$A$3:$A$2188<DATE(2018,1,1)),'Growth Index'!B$3:B$2188)/100-1) -> 0.27905963
A8: 2018 | B8: =IFERROR(LOOKUP(2,1/('Daily Prices'!$A$3:$A$2188<DATE(2018,2,1)+0),'Growth Index'!B$3:B$2188)/LOOKUP(2,1/('Daily Prices'!$A$3:$A$2188<DATE(2018,1,1)),'Growth Index'!B$3:B$2188)-1,LOOKUP(2,1/('Daily Prices'!$A$3:$A$2188<DATE(2018,2,1)+0),'Growth Index'!B$3:B$2188)/100-1) -> 0.056029583 | C8: =IFERROR(LOOKUP(2,1/('Daily Prices'!$A$3:$A$2188<DATE(2018,3,1)+0),'Growth Index'!B$3:B$2188)/LOOKUP(2,1/('Daily Prices'!$A$3:$A$2188<DATE(2018,2,1)),'Growth Index'!B$3:B$2188)-1,LOOKUP(2,1/('Daily Prices'!$A$3:$A$2188<DATE(2018,3,1)+0),'Growth Index'!B$3:B$2188)/100-1) -> -0.049519783 | D8: =IFERROR(LOOKUP(2,1/('Daily Prices'!$A$3:$A$2188<DATE(2018,4,1)+0),'Growth Index'!B$3:B$2188)/LOOKUP(2,1/('Daily Prices'!$A$3:$A$2188<DATE(2018,3,1)),'Growth Index'!B$3:B$2188)-1,LOOKUP(2,1/('Daily Prices'!$A$3:$A$2188<DATE(2018,4,1)+0),'Growth Index'!B$3:B$2188)/100-1) -> -0.035553434 | E8: =IFERROR(LOOKUP(2,1/('Daily Prices'!$A$3:$A$2188<DATE(2018,5,1)+0),'Growth Index'!B$3:B$2188)/LOOKUP(2,1/('Daily Prices'!$A$3:$A$2188<DATE(2018,4,1)),'Growth Index'!B$3:B$2188)-1,LOOKUP(2,1/('Daily Prices'!$A$3:$A$2188<DATE(2018,5,1)+0),'Growth Index'!B$3:B$2188)/100-1) -> 0.066477639 | F8: =IFERROR(LOOKUP(2,1/('Daily Prices'!$A$3:$A$2188<DATE(2018,6,1)+0),'Growth Index'!B$3:B$2188)/LOOKUP(2,1/('Daily Prices'!$A$3:$A$2188<DATE(2018,5,1)),'Growth Index'!B$3:B$2188)-1,LOOKUP(2,1/('Daily Prices'!$A$3:$A$2188<DATE(2018,6,1)+0),'Growth Index'!B$3:B$2188)/100-1) -> 0.0046080302 | G8: =IFERROR(LOOKUP(2,1/('Daily Prices'!$A$3:$A$2188<DATE(2018,7,1)+0),'Growth Index'!B$3:B$2188)/LOOKUP(2,1/('Daily Prices'!$A$3:$A$2188<DATE(2018,6,1)),'Growth Index'!B$3:B$2188)-1,LOOKUP(2,1/('Daily Prices'!$A$3:$A$2188<DATE(2018,7,1)+0),'Growth Index'!B$3:B$2188)/100-1) -> 0.002862208 | H8: =IFERROR(LOOKUP(2,1/('Daily Prices'!$A$3:$A$2188<DATE(2018,8,1)+0),'Growth Index'!B$3:B$2188)/LOOKUP(2,1/('Daily Prices'!$A$3:$A$2188<DATE(2018,7,1)),'Growth Index'!B$3:B$2188)-1,LOOKUP(2,1/('Daily Prices'!$A$3:$A$2188<DATE(2018,8,1)+0),'Growth Index'!B$3:B$2188)/100-1) -> 0.061628615 | I8: =IFERROR(LOOKUP(2,1/('Daily Prices'!$A$3:$A$2188<DATE(2018,9,1)+0),'Growth Index'!B$3:B$2188)/LOOKUP(2,1/('Daily Prices'!$A$3:$A$2188<DATE(2018,8,1)),'Growth Index'!B$3:B$2188)-1,LOOKUP(2,1/('Daily Prices'!$A$3:$A$2188<DATE(2018,9,1)+0),'Growth Index'!B$3:B$2188)/100-1) -> 0.027614582 | J8: =IFERROR(LOOKUP(2,1/('Daily Prices'!$A$3:$A$2188<DATE(2018,10,1)+0),'Growth Index'!B$3:B$2188)/LOOKUP(2,1/('Daily Prices'!$A$3:$A$2188<DATE(2018,9,1)),'Growth Index'!B$3:B$2188)-1,LOOKUP(2,1/('Daily Prices'!$A$3:$A$2188<DATE(2018,10,1)+0),'Growth Index'!B$3:B$2188)/100-1) -> -0.062567619 | K8: =IFERROR(LOOKUP(2,1/('Daily Prices'!$A$3:$A$2188<DATE(2018,11,1)+0),'Growth Index'!B$3:B$2188)/LOOKUP(2,1/('Daily Prices'!$A$3:$A$2188<DATE(2018,10,1)),'Growth Index'!B$3:B$2188)-1,LOOKUP(2,1/('Daily Prices'!$A$3:$A$2188<DATE(2018,11,1)+0),'Growth Index'!B$3:B$2188)/100-1) -> -0.049274936 | L8: =IFERROR(LOOKUP(2,1/('Daily Prices'!$A$3:$A$2188<DATE(2018,12,1)+0),'Growth Index'!B$3:B$2188)/LOOKUP(2,1/('Daily Prices'!$A$3:$A$2188<DATE(2018,11,1)),'Growth Index'!B$3:B$2188)-1,LOOKUP(2,1/('Daily Prices'!$A$3:$A$2188<DATE(2018,12,1)+0),'Growth Index'!B$3:B$2188)/100-1) -> 0.050875311 | M8: =IFERROR(LOOKUP(2,1/('Daily Prices'!$A$3:$A$2188<DATE(2019,1,1)),'Growth Index'!B$3:B$2188)/LOOKUP(2,1/('Daily Prices'!$A$3:$A$2188<DATE(2018,12,1)),'Growth Index'!B$3:B$2188)-1,LOOKUP(2,1/('Daily Prices'!$A$3:$A$2188<DATE(2019,1,1)),'Growth Index'!B$3:B$2188)/100-1) -> -0.0034803823 | N8: =IFERROR(LOOKUP(2,1/('Daily Prices'!$A$3:$A$2188<DATE(2019,1,1)),'Growth Index'!B$3:B$2188)/LOOKUP(2,1/('Daily Prices'!$A$3:$A$2188<DATE(2018,1,1)),'Growth Index'!B$3:B$2188)-1,LOOKUP(2,1/('Daily Prices'!$A$3:$A$2188<DATE(2019,1,1)),'Growth Index'!B$3:B$2188)/100-1) -> 0.059063043
A9: 2019 | B9: =IFERROR(LOOKUP(2,1/('Daily Prices'!$A$3:$A$2188<DATE(2019,2,1)+0),'Growth Index'!B$3:B$2188)/LOOKUP(2,1/('Daily Prices'!$A$3:$A$2188<DATE(2019,1,1)),'Growth Index'!B$3:B$2188)-1,LOOKUP(2,1/('Daily Prices'!$A$3:$A$2188<DATE(2019,2,1)+0),'Growth Index'!B$3:B$2188)/100-1) -> 0.00522231 | C9: =IFERROR(LOOKUP(2,1/('Daily Prices'!$A$3:$A$2188<DATE(2019,3,1)+0),'Growth Index'!B$3:B$2188)/LOOKUP(2,1/('Daily Prices'!$A$3:$A$2188<DATE(2019,2,1)),'Growth Index'!B$3:B$2188)-1,LOOKUP(2,1/('Daily Prices'!$A$3:$A$2188<DATE(2019,3,1)+0),'Growth Index'!B$3:B$2188)/100-1) -> -0.01073595 | D9: =IFERROR(LOOKUP(2,1/('Daily Prices'!$A$3:$A$2188<DATE(2019,4,1)+0),'Growth Index'!B$3:B$2188)/LOOKUP(2,1/('Daily Prices'!$A$3:$A$2188<DATE(2019,3,1)),'Growth Index'!B$3:B$2188)-1,LOOKUP(2,1/('Daily Prices'!$A$3:$A$2188<DATE(2019,4,1)+0),'Growth Index'!B$3:B$2188)/100-1) -> 0.078217737 | E9: =IFERROR(LOOKUP(2,1/('Daily Prices'!$A$3:$A$2188<DATE(2019,5,1)+0),'Growth Index'!B$3:B$2188)/LOOKUP(2,1/('Daily Prices'!$A$3:$A$2188<DATE(2019,4,1)),'Growth Index'!B$3:B$2188)-1,LOOKUP(2,1/('Daily Prices'!$A$3:$A$2188<DATE(2019,5,1)+0),'Growth Index'!B$3:B$2188)/100-1) -> 0.009273675 | F9: =IFERROR(LOOKUP(2,1/('Daily Prices'!$A$3:$A$2188<DATE(2019,6,1)+0),'Growth Index'!B$3:B$2188)/LOOKUP(2,1/('Daily Prices'!$A$3:$A$2188<DATE(2019,5,1)),'Growth Index'!B$3:B$2188)-1,LOOKUP(2,1/('Daily Prices'!$A$3:$A$2188<DATE(2019,6,1)+0),'Growth Index'!B$3:B$2188)/100-1) -> 0.017489697 | G9: =IFERROR(LOOKUP(2,1/('Daily Prices'!$A$3:$A$2188<DATE(2019,7,1)+0),'Growth Index'!B$3:B$2188)/LOOKUP(2,1/('Daily Prices'!$A$3:$A$2188<DATE(2019,6,1)),'Growth Index'!B$3:B$2188)-1,LOOKUP(2,1/('Daily Prices'!$A$3:$A$2188<DATE(2019,7,1)+0),'Growth Index'!B$3:B$2188)/100-1) -> -0.0080464922 | H9: =IFERROR(LOOKUP(2,1/('Daily Prices'!$A$3:$A$2188<DATE(2019,8,1)+0),'Growth Index'!B$3:B$2188)/LOOKUP(2,1/('Daily Prices'!$A$3:$A$2188<DATE(2019,7,1)),'Growth Index'!B$3:B$2188)-1,LOOKUP(2,1/('Daily Prices'!$A$3:$A$2188<DATE(2019,8,1)+0),'Growth Index'!B$3:B$2188)/100-1) -> -0.048573105 | I9: =IFERROR(LOOKUP(2,1/('Daily Prices'!$A$3:$A$2188<DATE(2019,9,1)+0),'Growth Index'!B$3:B$2188)/LOOKUP(2,1/('Daily Prices'!$A$3:$A$2188<DATE(2019,8,1)),'Growth Index'!B$3:B$2188)-1,LOOKUP(2,1/('Daily Prices'!$A$3:$A$2188<DATE(2019,9,1)+0),'Growth Index'!B$3:B$2188)/100-1) -> -0.0039574591 | J9: =IFERROR(LOOKUP(2,1/('Daily Prices'!$A$3:$A$2188<DATE(2019,10,1)+0),'Growth Index'!B$3:B$2188)/LOOKUP(2,1/('Daily Prices'!$A$3:$A$2188<DATE(2019,9,1)),'Growth Index'!B$3:B$2188)-1,LOOKUP(2,1/('Daily Prices'!$A$3:$A$2188<DATE(2019,10,1)+0),'Growth Index'!B$3:B$2188)/100-1) -> 0.035747127 | K9: =IFERROR(LOOKUP(2,1/('Daily Prices'!$A$3:$A$2188<DATE(2019,11,1)+0),'Growth Index'!B$3:B$2188)/LOOKUP(2,1/('Daily Prices'!$A$3:$A$2188<DATE(2019,10,1)),'Growth Index'!B$3:B$2188)-1,LOOKUP(2,1/('Daily Prices'!$A$3:$A$2188<DATE(2019,11,1)+0),'Growth Index'!B$3:B$2188)/100-1) -> 0.037802455 | L9: =IFERROR(LOOKUP(2,1/('Daily Prices'!$A$3:$A$2188<DATE(2019,12,1)+0),'Growth Index'!B$3:B$2188)/LOOKUP(2,1/('Daily Prices'!$A$3:$A$2188<DATE(2019,11,1)),'Growth Index'!B$3:B$2188)-1,LOOKUP(2,1/('Daily Prices'!$A$3:$A$2188<DATE(2019,12,1)+0),'Growth Index'!B$3:B$2188)/100-1) -> 0.016565555 | M9: =IFERROR(LOOKUP(2,1/('Daily Prices'!$A$3:$A$2188<DATE(2020,1,1)),'Growth Index'!B$3:B$2188)/LOOKUP(2,1/('Daily Prices'!$A$3:$A$2188<DATE(2019,12,1)),'Growth Index'!B$3:B$2188)-1,LOOKUP(2,1/('Daily Prices'!$A$3:$A$2188<DATE(2020,1,1)),'Growth Index'!B$3:B$2188)/100-1) -> 0.011274505 | N9: =IFERROR(LOOKUP(2,1/('Daily Prices'!$A$3:$A$2188<DATE(2020,1,1)),'Growth Index'!B$3:B$2188)/LOOKUP(2,1/('Daily Prices'!$A$3:$A$2188<DATE(2019,1,1)),'Growth Index'!B$3:B$2188)-1,LOOKUP(2,1/('Daily Prices'!$A$3:$A$2188<DATE(2020,1,1)),'Growth Index'!B$3:B$2188)/100-1) -> 0.14376629
A10: 2020 | B10: =IFERROR(LOOKUP(2,1/('Daily Prices'!$A$3:$A$2188<DATE(2020,2,1)+0),'Growth Index'!B$3:B$2188)/LOOKUP(2,1/('Daily Prices'!$A$3:$A$2188<DATE(2020,1,1)),'Growth Index'!B$3:B$2188)-1,LOOKUP(2,1/('Daily Prices'!$A$3:$A$2188<DATE(2020,2,1)+0),'Growth Index'!B$3:B$2188)/100-1) -> -0.01285338 | C10: =IFERROR(LOOKUP(2,1/('Daily Prices'!$A$3:$A$2188<DATE(2020,3,1)+0),'Growth Index'!B$3:B$2188)/LOOKUP(2,1/('Daily Prices'!$A$3:$A$2188<DATE(2020,2,1)),'Growth Index'!B$3:B$2188)-1,LOOKUP(2,1/('Daily Prices'!$A$3:$A$2188<DATE(2020,3,1)+0),'Growth Index'!B$3:B$2188)/100-1) -> -0.059577409 | D10: =IFERROR(LOOKUP(2,1/('Daily Prices'!$A$3:$A$2188<DATE(2020,4,1)+0),'Growth Index'!B$3:B$2188)/LOOKUP(2,1/('Daily Prices'!$A$3:$A$2188<DATE(2020,3,1)),'Growth Index'!B$3:B$2188)-1,LOOKUP(2,1/('Daily Prices'!$A$3:$A$2188<DATE(2020,4,1)+0),'Growth Index'!B$3:B$2188)/100-1) -> -0.23053328 | E10: =IFERROR(LOOKUP(2,1/('Daily Prices'!$A$3:$A$2188<DATE(2020,5,1)+0),'Growth Index'!B$3:B$2188)/LOOKUP(2,1/('Daily Prices'!$A$3:$A$2188<DATE(2020,4,1)),'Growth Index'!B$3:B$2188)-1,LOOKUP(2,1/('Daily Prices'!$A$3:$A$2188<DATE(2020,5,1)+0),'Growth Index'!B$3:B$2188)/100-1) -> 0.14419232 | F10: =IFERROR(LOOKUP(2,1/('Daily Prices'!$A$3:$A$2188<DATE(2020,6,1)+0),'Growth Index'!B$3:B$2188)/LOOKUP(2,1/('Daily Prices'!$A$3:$A$2188<DATE(2020,5,1)),'Growth Index'!B$3:B$2188)-1,LOOKUP(2,1/('Daily Prices'!$A$3:$A$2188<DATE(2020,6,1)+0),'Growth Index'!B$3:B$2188)/100-1) -> -0.038363325 | G10: =IFERROR(LOOKUP(2,1/('Daily Prices'!$A$3:$A$2188<DATE(2020,7,1)+0),'Growth Index'!B$3:B$2188)/LOOKUP(2,1/('Daily Prices'!$A$3:$A$2188<DATE(2020,6,1)),'Growth Index'!B$3:B$2188)-1,LOOKUP(2,1/('Daily Prices'!$A$3:$A$2188<DATE(2020,7,1)+0),'Growth Index'!B$3:B$2188)/100-1) -> 0.07684716 | H10: =IFERROR(LOOKUP(2,1/('Daily Prices'!$A$3:$A$2188<DATE(2020,8,1)+0),'Growth Index'!B$3:B$2188)/LOOKUP(2,1/('Daily Prices'!$A$3:$A$2188<DATE(2020,7,1)),'Growth Index'!B$3:B$2188)-1,LOOKUP(2,1/('Daily Prices'!$A$3:$A$2188<DATE(2020,8,1)+0),'Growth Index'!B$3:B$2188)/100-1) -> 0.077073703 | I10: =IFERROR(LOOKUP(2,1/('Daily Prices'!$A$3:$A$2188<DATE(2020,9,1)+0),'Growth Index'!B$3:B$2188)/LOOKUP(2,1/('Daily Prices'!$A$3:$A$2188<DATE(2020,8,1)),'Growth Index'!B$3:B$2188)-1,LOOKUP(2,1/('Daily Prices'!$A$3:$A$2188<DATE(2020,9,1)+0),'Growth Index'!B$3:B$2188)/100-1) -> 0.027159917 | J10: =IFERROR(LOOKUP(2,1/('Daily Prices'!$A$3:$A$2188<DATE(2020,10,1)+0),'Growth Index'!B$3:B$2188)/LOOKUP(2,1/('Daily Prices'!$A$3:$A$2188<DATE(2020,9,1)),'Growth Index'!B$3:B$2188)-1,LOOKUP(2,1/('Daily Prices'!$A$3:$A$2188<DATE(2020,10,1)+0),'Growth Index'!B$3:B$2188)/100-1) -> -0.014506467 | K10: =IFERROR(LOOKUP(2,1/('Daily Prices'!$A$3:$A$2188<DATE(2020,11,1)+0),'Growth Index'!B$3:B$2188)/LOOKUP(2,1/('Daily Prices'!$A$3:$A$2188<DATE(2020,10,1)),'Growth Index'!B$3:B$2188)-1,LOOKUP(2,1/('Daily Prices'!$A$3:$A$2188<DATE(2020,11,1)+0),'Growth Index'!B$3:B$2188)/100-1) -> 0.04061529 | L10: =IFERROR(LOOKUP(2,1/('Daily Prices'!$A$3:$A$2188<DATE(2020,12,1)+0),'Growth Index'!B$3:B$2188)/LOOKUP(2,1/('Daily Prices'!$A$3:$A$2188<DATE(2020,11,1)),'Growth Index'!B$3:B$2188)-1,LOOKUP(2,1/('Daily Prices'!$A$3:$A$2188<DATE(2020,12,1)+0),'Growth Index'!B$3:B$2188)/100-1) -> 0.11449594 | M10: =IFERROR(LOOKUP(2,1/('Daily Prices'!$A$3:$A$2188<DATE(2021,1,1)),'Growth Index'!B$3:B$2188)/LOOKUP(2,1/('Daily Prices'!$A$3:$A$2188<DATE(2020,12,1)),'Growth Index'!B$3:B$2188)-1,LOOKUP(2,1/('Daily Prices'!$A$3:$A$2188<DATE(2021,1,1)),'Growth Index'!B$3:B$2188)/100-1) -> 0.081577188 | N10: =IFERROR(LOOKUP(2,1/('Daily Prices'!$A$3:$A$2188<DATE(2021,1,1)),'Growth Index'!B$3:B$2188)/LOOKUP(2,1/('Daily Prices'!$A$3:$A$2188<DATE(2020,1,1)),'Growth Index'!B$3:B$2188)-1,LOOKUP(2,1/('Daily Prices'!$A$3:$A$2188<DATE(2021,1,1)),'Growth Index'!B$3:B$2188)/100-1) -> 0.15750305
A11: 2021 | B11: =IFERROR(LOOKUP(2,1/('Daily Prices'!$A$3:$A$2188<DATE(2021,2,1)+0),'Growth Index'!B$3:B$2188)/LOOKUP(2,1/('Daily Prices'!$A$3:$A$2188<DATE(2021,1,1)),'Growth Index'!B$3:B$2188)-1,LOOKUP(2,1/('Daily Prices'!$A$3:$A$2188<DATE(2021,2,1)+0),'Growth Index'!B$3:B$2188)/100-1) -> -0.030691501 | C11: =IFERROR(LOOKUP(2,1/('Daily Prices'!$A$3:$A$2188<DATE(2021,3,1)+0),'Growth Index'!B$3:B$2188)/LOOKUP(2,1/('Daily Prices'!$A$3:$A$2188<DATE(2021,2,1)),'Growth Index'!B$3:B$2188)-1,LOOKUP(2,1/('Daily Prices'!$A$3:$A$2188<DATE(2021,3,1)+0),'Growth Index'!B$3:B$2188)/100-1) -> 0.060800976 | D11: =IFERROR(LOOKUP(2,1/('Daily Prices'!$A$3:$A$2188<DATE(2021,4,1)+0),'Growth Index'!B$3:B$2188)/LOOKUP(2,1/('Daily Prices'!$A$3:$A$2188<DATE(2021,3,1)),'Growth Index'!B$3:B$2188)-1,LOOKUP(2,1/('Daily Prices'!$A$3:$A$2188<DATE(2021,4,1)+0),'Growth Index'!B$3:B$2188)/100-1) -> 0.0083331993 | E11: =IFERROR(LOOKUP(2,1/('Daily Prices'!$A$3:$A$2188<DATE(2021,5,1)+0),'Growth Index'!B$3:B$2188)/LOOKUP(2,1/('Daily Prices'!$A$3:$A$2188<DATE(2021,4,1)),'Growth Index'!B$3:B$2188)-1,LOOKUP(2,1/('Daily Prices'!$A$3:$A$2188<DATE(2021,5,1)+0),'Growth Index'!B$3:B$2188)/100-1) -> -0.014679913 | F11: =IFERROR(LOOKUP(2,1/('Daily Prices'!$A$3:$A$2188<DATE(2021,6,1)+0),'Growth Index'!B$3:B$2188)/LOOKUP(2,1/('Daily Prices'!$A$3:$A$2188<DATE(2021,5,1)),'Growth Index'!B$3:B$2188)-1,LOOKUP(2,1/('Daily Prices'!$A$3:$A$2188<DATE(2021,6,1)+0),'Growth Index'!B$3:B$2188)/100-1) -> 0.064676658 | G11: =IFERROR(LOOKUP(2,1/('Daily Prices'!$A$3:$A$2188<DATE(2021,7,1)+0),'Growth Index'!B$3:B$2188)/LOOKUP(2,1/('Daily Prices'!$A$3:$A$2188<DATE(2021,6,1)),'Growth Index'!B$3:B$2188)-1,LOOKUP(2,1/('Daily Prices'!$A$3:$A$2188<DATE(2021,7,1)+0),'Growth Index'!B$3:B$2188)/100-1) -> 0.010498592 | H11: =IFERROR(LOOKUP(2,1/('Daily Prices'!$A$3:$A$2188<DATE(2021,8,1)+0),'Growth Index'!B$3:B$2188)/LOOKUP(2,1/('Daily Prices'!$A$3:$A$2188<DATE(2021,7,1)),'Growth Index'!B$3:B$2188)-1,LOOKUP(2,1/('Daily Prices'!$A$3:$A$2188<DATE(2021,8,1)+0),'Growth Index'!B$3:B$2188)/100-1) -> 0.001984082 | I11: =IFERROR(LOOKUP(2,1/('Daily Prices'!$A$3:$A$2188<DATE(2021,9,1)+0),'Growth Index'!B$3:B$2188)/LOOKUP(2,1/('Daily Prices'!$A$3:$A$2188<DATE(2021,8,1)),'Growth Index'!B$3:B$2188)-1,LOOKUP(2,1/('Daily Prices'!$A$3:$A$2188<DATE(2021,9,1)+0),'Growth Index'!B$3:B$2188)/100-1) -> 0.094425716 | J11: =IFERROR(LOOKUP(2,1/('Daily Prices'!$A$3:$A$2188<DATE(2021,10,1)+0),'Growth Index'!B$3:B$2188)/LOOKUP(2,1/('Daily Prices'!$A$3:$A$2188<DATE(2021,9,1)),'Growth Index'!B$3:B$2188)-1,LOOKUP(2,1/('Daily Prices'!$A$3:$A$2188<DATE(2021,10,1)+0),'Growth Index'!B$3:B$2188)/100-1) -> 0.027348473 | K11: =IFERROR(LOOKUP(2,1/('Daily Prices'!$A$3:$A$2188<DATE(2021,11,1)+0),'Growth Index'!B$3:B$2188)/LOOKUP(2,1/('Daily Prices'!$A$3:$A$2188<DATE(2021,10,1)),'Growth Index'!B$3:B$2188)-1,LOOKUP(2,1/('Daily Prices'!$A$3:$A$2188<DATE(2021,11,1)+0),'Growth Index'!B$3:B$2188)/100-1) -> 0.0030539678 | L11: =IFERROR(LOOKUP(2,1/('Daily Prices'!$A$3:$A$2188<DATE(2021,12,1)+0),'Growth Index'!B$3:B$2188)/LOOKUP(2,1/('Daily Prices'!$A$3:$A$2188<DATE(2021,11,1)),'Growth Index'!B$3:B$2188)-1,LOOKUP(2,1/('Daily Prices'!$A$3:$A$2188<DATE(2021,12,1)+0),'Growth Index'!B$3:B$2188)/100-1) -> -0.037804351 | M11: =IFERROR(LOOKUP(2,1/('Daily Prices'!$A$3:$A$2188<DATE(2022,1,1)),'Growth Index'!B$3:B$2188)/LOOKUP(2,1/('Daily Prices'!$A$3:$A$2188<DATE(2021,12,1)),'Growth Index'!B$3:B$2188)-1,LOOKUP(2,1/('Daily Prices'!$A$3:$A$2188<DATE(2022,1,1)),'Growth Index'!B$3:B$2188)/100-1) -> 0.02083506 | N11: =IFERROR(LOOKUP(2,1/('Daily Prices'!$A$3:$A$2188<DATE(2022,1,1)),'Growth Index'!B$3:B$2188)/LOOKUP(2,1/('Daily Prices'!$A$3:$A$2188<DATE(2021,1,1)),'Growth Index'!B$3:B$2188)-1,LOOKUP(2,1/('Daily Prices'!$A$3:$A$2188<DATE(2022,1,1)),'Growth Index'!B$3:B$2188)/100-1) -> 0.21994131
